Workbook

Sheet Part1-Individual
A1: You are part of a financial consulting team tasked with advising a startup client looking to invest in one of three diversified investment portfolios.
A2: Each portfolio has various potential outcomes, probabilities, associated risks, and strategic implications. Your goal is to analyze these portfolios in depth and provide a well-justified recommendation.
A4: Investment Portfolios Overview
A6: Portfolio | B6: Growth Outcome | C6: Payoff ($) | D6: Probability
A7: A | B7: High | C7: 300000 | D7: 0.2
B8: Moderate | C8: 120000 | D8: 0.5
B9: Low | C9: 30000 | D9: 0.25
B10: Total Loss | C10: -100000 | D10: 0.05
A11: B | B11: High | C11: 400000 | D11: 0.15
B12: Moderate | C12: 150000 | D12: 0.5
B13: Low | C13: 50000 | D13: 0.25
B14: Total Loss | C14: -80000 | D14: 0.1
A15: C | B15: High | C15: 250000 | D15: 0.25
B16: Moderate | C16: 90000 | D16: 0.5
B17: Low | C17: 20000 | D17: 0.15
B18: Total Loss | C18: -60000 | D18: 0.1
A20: Part 1: Detailed Individual Analysis - will not be graded but must be submitted prior to joining a group
A21: Before joining a group, you must gain a comprehensive understanding of each portfolio.
A23: Tasks
A24: 1. Calculate the Payoff Strategies for each investment option using Risk Modelling as you learned in class.
B26: For each type of decision-making, create a table for each portfolio.
A28: 2. Sensitivity Analysis: Assess how sensitive the average payoff is to changes in the probability of the high-growth scenario (e.g., what happens if the probability increases or decreases by 10% between 10 to 90%).
A31: Investment Decision Analysis Using Risk Modelling
A33: A startup company is evaluating three investment portfolios (A, B, and C) under uncertain market conditions. Each portfolio has different payoffs and probabilities across four possible growth outcomes:
A35: High Growth
A36: Moderate Growth
A37: Low Growth
A38: Total Loss
A42: 🔹 Part 1: Quantitative Analysis
A44: 1. Risk Modelling & Payoff Analysis
A46: For each portfolio:
A48: Calculate:
A49: Expected Payoff (Expected Value)
... A122: Plot graphs and interpret results

Sheet Final
A1: 1. Calculate the Payoff Strategies for each investment option using Risk Modelling as you learned in class.
A3: Portfolio | B3: Growth Outcome | C3: Payoff ($) | D3: Probability | E3: Average Payoff ($) | F3: Expected Payoff ($) | G3: (Payoff-expected)^2 * probability | H3: Variance | I3: Standard Deviation | J3: Return to risk Ratio
A4: A | B4: High | C4: 300000 | D4: 0.2 | E4: =C4*D4 -> 60000 | F4: =SUM(E4:E7) -> 122500 | G4: =((C4-$F$4)^2 *D4) -> 6301250000 | H4: =SUM(G4:G7) -> 10918750000 | I4: =SQRT(H4) -> 104492.82 | J4: =F4/I4 -> 1.1723293
B5: Moderate | C5: 120000 | D5: 0.5 | E5: =C5*D5 -> 60000 | G5: =((C5-$F$4)^2 *D5) -> 3125000
B6: Low | C6: 30000 | D6: 0.25 | E6: =C6*D6 -> 7500 | G6: =((C6-$F$4)^2 *D6) -> 2139062500
B7: Total Loss | C7: -100000 | D7: 0.05 | E7: =C7*D7 -> -5000 | G7: =((C7-$F$4)^2 *D7) -> 2475312500
A9: Portfolio | B9: Growth Outcome | C9: Payoff ($) | D9: Probability | E9: Average Payoff ($) | F9: Expected Payoff | G9: (Payoff-expected)^2 * probability | H9: Variance | I9: Standard Deviation | J9: Return to risk Ratio
A10: B | B10: High | C10: 400000 | D10: 0.15 | E10: =C10*D10 -> 60000 | F10: =SUM(E10:E13) -> 139500 | G10: =(C10-$F$10)^2 *D10 -> 10179037500 | H10: =SUM(G10:G13) -> 17054750000 | I10: =SQRT(H10) -> 130593.84 | J10: =F10/I10 -> 1.0681974 | L10: Best Expected Payoff ($) (B) | M10: =MAX(F4,F10,F16) -> 139500
B11: Moderate | C11: 150000 | D11: 0.5 | E11: =C11*D11 -> 75000 | G11: =(C11-$F$10)^2 *D11 -> 55125000 | L11: Opportunity Loss (Portfolio A) | M11: =F4-M10 -> -17000
B12: Low | C12: 50000 | D12: 0.25 | E12: =C12*D12 -> 12500 | G12: =(C12-$F$10)^2 *D12 -> 2002562500 | L12: Opportunity Loss (Portfolio C) | M12: =F16-M10 -> -35000
B13: Total Loss | C13: -80000 | D13: 0.1 | E13: =C13*D13 -> -8000 | G13: =(C13-$F$10)^2 *D13 -> 4818025000 | L13: Least Risk Portfolio (Portfolio C) | M13: =I16 -> 95784.915
A15: Portfolio | B15: Growth Outcome | C15: Payoff ($) | D15: Probability | E15: Average Payoff ($) | F15: Expected Payoff | G15: (Payoff-expected)^2 * probability | H15: Variance | I15: Standard Deviation | J15: Return to risk Ratio
A16: C | B16: High | C16: 250000 | D16: 0.25 | E16: =C16*D16 -> 62500 | F16: =SUM(E16:E19) -> 104500 | G16: =(C16-$F$16)^2 *D16 -> 5292562500 | H16: =SUM(G16:G19) -> 9174750000 | I16: =SQRT(H16) -> 95784.915 | J16: =F16/I16 -> 1.090986
B17: Moderate | C17: 90000 | D17: 0.5 | E17: =C17*D17 -> 45000 | G17: =(C17-$F$16)^2 *D17 -> 105125000
B18: Low | C18: 20000 | D18: 0.15 | E18: =C18*D18 -> 3000 | G18: =(C18-$F$16)^2 *D18 -> 1071037500
B19: Total Loss | C19: -60000 | D19: 0.1 | E19: =C19*D19 -> -6000 | G19: =(C19-$F$16)^2 *D19 -> 2706025000
A21: 2. Sensitivity Analysis: Assess how sensitive the average payoff is to changes in the probability of the high-growth scenario (e.g., what happens if the probability increases or decreases by 10% between 10 to 90%).
A23: 10% increase and decrease
A24: Portfolio | B24: Growth Outcome | C24: Payoff ($) | D24: Probability | E24: 10% + | F24: 10% - | G24: Average Payoff (10% +) | H24: Average Payoff (Actual) | I24: Average Payoff (10% -) | J24: Expected Payoff (10% +) | K24: Expected Payoff (Actual) | L24: Expected Payoff (10% -)
A25: A | B25: High | C25: 300000 | D25: 0.2 | E25: =D25+0.1 -> 0.3 | F25: =D25-0.1 -> 0.1 | G25: =C25*E25 -> 90000 | H25: =C25*D25 -> 60000 | I25: =C25*F25 -> 30000 | J25: =SUM(G25:G28) -> 144687.5 | K25: =SUM(H25:H28) -> 122500 | L25: =SUM(I25:I28) -> 100312.5
B26: Moderate | C26: 120000 | D26: 0.5 | E26: =$D26*((1-E$25)/SUM($D$26:$D$28)) -> 0.4375 | F26: =$D26*((1-F$25)/SUM($D$26:$D$28)) -> 0.5625 | G26: =C26*E26 -> 52500 | H26: =C26*D26 -> 60000 | I26: =C26*F26 -> 67500
B27: Low | C27: 30000 | D27: 0.25 | E27: =$D27*((1-E$25)/SUM($D$26:$D$28)) -> 0.21875 | F27: =$D27*((1-F$25)/SUM($D$26:$D$28)) -> 0.28125 | G27: =C27*E27 -> 6562.5 | H27: =C27*D27 -> 7500 | I27: =C27*F27 -> 8437.5
B28: Total Loss | C28: -100000 | D28: 0.05 | E28: =$D28*((1-E$25)/SUM($D$26:$D$28)) -> 0.04375 | F28: =$D28*((1-F$25)/SUM($D$26:$D$28)) -> 0.05625 | G28: =C28*E28 -> -4375 | H28: =C28*D28 -> -5000 | I28: =C28*F28 -> -5625
A30: Portfolio | B30: Growth Outcome | C30: Payoff ($) | D30: Probability | E30: 10% + | F30: 10% - | G30: Average Payoff (10% +) | H30: Average Payoff (Actual) | I30: Average Payoff (10% -) | J30: Expected Payoff (10% +) | K30: Expected Payoff (Actual) | L30: Expected Payoff (10% -)
A31: B | B31: High | C31: 400000 | D31: 0.15 | E31: =D31+0.1 -> 0.25 | F31: =D31-0.1 -> 0.05 | G31: =C31*E31 -> 100000 | H31: =C31*D31 -> 60000 | I31: =C31*F31 -> 20000 | J31: =SUM(G31:G34) -> 170147.06 | K31: =SUM(H31:H34) -> 139500 | L31: =SUM(I31:I34) -> 108852.94
B32: Moderate | C32: 150000 | D32: 0.5 | E32: =$D32*((1-E$31)/SUM($D$32:$D$34)) -> 0.44117647 | F32: =$D32*((1-F$31)/SUM($D$32:$D$34)) -> 0.55882353 | G32: =C32*E32 -> 66176.471 | H32: =C32*D32 -> 75000 | I32: =C32*F32 -> 83823.529
B33: Low | C33: 50000 | D33: 0.25 | E33: =$D33*((1-E$31)/SUM($D$32:$D$34)) -> 0.22058824 | F33: =$D33*((1-F$31)/SUM($D$32:$D$34)) -> 0.27941176 | G33: =C33*E33 -> 11029.412 | H33: =C33*D33 -> 12500 | I33: =C33*F33 -> 13970.588
B34: Total Loss | C34: -80000 | D34: 0.1 | E34: =$D34*((1-E$31)/SUM($D$32:$D$34)) -> 0.088235294 | F34: =$D34*((1-F$31)/SUM($D$32:$D$34)) -> 0.11176471 | G34: =C34*E34 -> -7058.8235 | H34: =C34*D34 -> -8000 | I34: =C34*F34 -> -8941.1765
A36: Portfolio | B36: Growth Outcome | C36: Payoff ($) | D36: Probability | E36: 10% + | F36: 10% - | G36: Average Payoff (10% +) | H36: Average Payoff (Actual) | I36: Average Payoff (10% -) | J36: Expected Payoff (10% +) | K36: Expected Payoff (Actual) | L36: Expected Payoff (10% -)
A37: C | B37: High | C37: 250000 | D37: 0.25 | E37: =D37+0.1 -> 0.35 | F37: =D37-0.1 -> 0.15 | G37: =C37*E37 -> 87500 | H37: =C37*D37 -> 62500 | I37: =C37*F37 -> 37500 | J37: =SUM(G37:G40) -> 123900 | K37: =SUM(H37:H40) -> 104500 | L37: =SUM(I37:I40) -> 85100
B38: Moderate | C38: 90000 | D38: 0.5 | E38: =$D38*((1-E$37)/SUM($D$38:$D$40)) -> 0.43333333 | F38: =$D38*((1-F$37)/SUM($D$38:$D$40)) -> 0.56666667 | G38: =C38*E38 -> 39000 | H38: =C38*D38 -> 45000 | I38: =C38*F38 -> 51000
B39: Low | C39: 20000 | D39: 0.15 | E39: =$D39*((1-E$37)/SUM($D$38:$D$40)) -> 0.13 | F39: =$D39*((1-F$37)/SUM($D$38:$D$40)) -> 0.17 | G39: =C39*E39 -> 2600 | H39: =C39*D39 -> 3000 | I39: =C39*F39 -> 3400
B40: Total Loss | C40: -60000 | D40: 0.1 | E40: =$D40*((1-E$37)/SUM($D$38:$D$40)) -> 0.086666667 | F40: =$D40*((1-F$37)/SUM($D$38:$D$40)) -> 0.11333333 | G40: =C40*E40 -> -5200 | H40: =C40*D40 -> -6000 | I40: =C40*F40 -> -6800
A43: 20% increase and decrease
A44: Portfolio | B44: Growth Outcome | C44: Payoff ($) | D44: Probability | E44: 20% + | F44: 20% - | G44: Average Payoff (20% +) | H44: Average Payoff (Actual) | I44: Average Payoff (20% -) | J44: Expected Payoff (20% +) | K44: Expected Payoff (Actual) | L44: Expected Payoff (20% -)
A45: A | B45: High | C45: 300000 | D45: 0.2 | E45: =D45+0.2 -> 0.4 | F45: =D45-0.2 -> 0 | G45: =C45*E45 -> 120000 | H45: =C45*D45 -> 60000 | I45: =C45*F45 -> 0 | J45: =SUM(G45:G48) -> 166875 | K45: =SUM(H45:H48) -> 122500 | L45: =SUM(I45:I48) -> 78125
B46: Moderate | C46: 120000 | D46: 0.5 | E46: =$D46*((1-E$45)/SUM($D$46:$D$48)) -> 0.375 | F46: =$D46*((1-F$45)/SUM($D$46:$D$48)) -> 0.625 | G46: =C46*E46 -> 45000 | H46: =C46*D46 -> 60000 | I46: =C46*F46 -> 75000
B47: Low | C47: 30000 | D47: 0.25 | E47: =$D47*((1-E$45)/SUM($D$46:$D$48)) -> 0.1875 | F47: =$D47*((1-F$45)/SUM($D$46:$D$48)) -> 0.3125 | G47: =C47*E47 -> 5625 | H47: =C47*D47 -> 7500 | I47: =C47*F47 -> 9375
B48: Total Loss | C48: -100000 | D48: 0.05 | E48: =$D48*((1-E$45)/SUM($D$46:$D$48)) -> 0.0375 | F48: =$D48*((1-F$45)/SUM($D$46:$D$48)) -> 0.0625 | G48: =C48*E48 -> -3750 | H48: =C48*D48 -> -5000 | I48: =C48*F48 -> -6250
A50: Portfolio | B50: Growth Outcome | C50: Payoff ($) | D50: Probability | E50: 20% + | F50: 20% - | G50: Average Payoff (20% +) | H50: Average Payoff (Actual) | I50: Average Payoff (20% -) | J50: Expected Payoff (20% +) | K50: Expected Payoff (Actual) | L50: Expected Payoff (20% -)
...

Sheet Report
A1: Report
A3: 2. Discuss: (Approximately 20-30 lines in total)
A4: (a) interpret the implications of the average payoffs in terms of potential growth for the startup.
A5: Portfolio A offers substantial growth potential with an average payoff of $122,500, making it a good choice for startups. Portfolio B has the highest expected value of $139,500, offering higher growth potential. Portfolio C has the lowest projected value, with an average payback of $104,500, suggesting a less volatile approach. All three portfolios offer positive expected returns, with different levels of potential growth and risk. Portfolio B is the best choice for aggressive growth, while Portfolio A provides significant returns. Portfolio C offers the lowest returns and may be more suitable for a risk-averse investing approach. The startups should choose the portfolio that best fits their growth goals and risk tolerance.
A8: (b) how the Best and Worst-Case Scenarios for each portfolio could impact the startup's long-term strategy.
A9: Portfolio A
A10: Best case: payoff is 300,000 and its probability is 0.2 it is lower compare to other portfolio.
A11: Worse case : -100,000 total loss and its probability is low compare to other it is 0.05
A12: It is a moderate portfolio and can be one option for startup.
A14: Portfolio B
A15: Highest : payoff is 400,000 and its probability is 0.15 and expected payoff for this is also high 600,000, and it is highest potential payoff compare to other portfolio.
A16: Worse case: -80,000 total loss and its probability is 0.1 is high compare to A and same as C .
... A38: Which is the best portfolio, and why? (5-10 lines that explain how you arrived at the decision interpreting your analysis.)
B41: Expected Payoff: | C41: Standard Deviation (Risk): | D41: Best-Case Scenario: | E41: Worst-Case Scenario: | F41: Volatility:
A42: Portfolio A | B42: 122500 | C42: 98392.95 | D42: 300000 | E42: -100000 | F42: Moderate
A43: Portfolio B | B43: 139500 | C43: 130599.74 | D43: 400000 | E43: -80000 | F43: High
A44: Portfolio C | B44: 104500 | C44: 95754.34 | D44: 250000 | E44: -60000 | F44: Low
A47: According to our analysis, Portfolio B is the best portfolio.
A49: 1. Maximum Expected payoff: With an expected payoff of $139,500, Portfolio B has the maximum potential for growth.
A50: 2. Large Potential Returns: If the high-growth scenario comes to pass, Portfolio B has the potential to generate large financial gains based on the high projected payoff.
A51: 3. Risk Consideration: While Portfolio B has the maximum standard deviation ($130,599.74), which suggests a higher level of risk, this is reasonable for companies who are prepared to assume greater risk in exchange for big returns.
A52: 4. Strategic Fit for Aggressive Growth: A startup's goal of aggressive growth and market expansion is well matched with the large potential returns.
A53: 5. Risk-Return Balance: Portfolio B is a good option as it focuses on growth because its high volatile nature is acceptable as the returns are high
A54: 6. Worst-Case scenario: Although high loss is possible, the possibility of large return makes it worth the risk.
A55: 7. Opportunity Cost: If we select Portfolio B, it lowers the chance cost of deciding against the portfolio with the highest expected return.
A56: 8. Long-Term Strategy: The high possible profits provide support for long-term strategic goals like reinvestment, expansion, and achieving a larger market share.
A57: 9. Competitive Advantage: Higher returns on investment may provide a benefit over competitors by releasing up additional funds for research and development.
A58: 10. Growth Potential: Taking everything into account, Portfolio B helps the firm reach its goal of maximising its financial results and securing major expansion.
A61: 4. Sensitivity analysis
... A70: In 80% increase for Portfolio A, we have a probability of 1 for high growth and 0 for all the rest, resulting in zero payoffs for moderate, low and total loss scenarios

Sheet References
A1: Sr. No. | B1: References
A2: 1 | B2: Bobbitt, Z. (2021, September 3). How to calculate the variance of a probability distribution. Statology. https://www.statology.org/variance-of-probability-distribution/
A3: 2 | B3: Bloch, B. J. (2022a, May 9).How risky is your portfolio? Investopedia. https://www.investopedia.com/articles/pf/06/riskyportfolio.asp#:~:text=As%20a%20general%20rule%2C%20if,lose%20with%20a%20particular%20portfolio
A4: 3 | B4: McFarlane, G. (2023, December 11). The best portfolio balance. Investopedia. https://www.investopedia.com/financial-edge/0412/the-best-portfolio-balance.aspx
A5: 4 | B5: Kenton, W. (2024, June 27). What is sensitivity analysis? Investopedia. https://www.investopedia.com/terms/s/sensitivityanalysis.asp
A6: 5 | B6: https://chatgpt.com/
A7: 6 | B7: Corp, S. F. (2023, February 21). Investing if you are risk averse. Synovus. https://www.synovus.com/personal/resource-center/financial-newsletters/2022/september/investing-if-you-are-risk-averse/
